Workbook

Sheet 🏠 Dashboard
A1: AML / KYC / EDD — COMPLIANCE MONITORING DASHBOARD (50 Records)
A5: Report Period: FY 2024 | 50 Customer Records | As of 03 Jun 2026 | Compliance & Risk Management
B7: TOTAL CUSTOMERS | E7: HIGH RISK ALERTS | H7: KYC COMPLETED | K7: EDD CASES OPEN | N7: SAR FILINGS | Q7: PEP CUSTOMERS
B8: =IFERROR(COUNTA('📋 KYC Register'!A4:A53),0) | E8: =IFERROR(COUNTIF('🚨 AML Alerts'!H4:H53,"High")+COUNTIF('🚨 AML Alerts'!H4:H53,"Critical"),0) | H8: 25 | K8: =IFERROR(COUNTIF('🔍 EDD Cases'!O4:O53,"Open")+COUNTIF('🔍 EDD Cases'!O4:O53,"In Progress")+COUNTIF('🔍 EDD Cases'!O4:O53,"Overdue")+COUNTIF('🔍 EDD Cases'!O4:O53,"Escalated")+COUNTIF('🔍 EDD Cases'!O4:O53,"Pending Docs"),0) | N8: 19 | Q8: =IFERROR(COUNTIF('📋 KYC Register'!N4:N53,"Yes"),0)
B9: Base dataset | E9: =IFERROR("Open: "&COUNTIF('🚨 AML Alerts'!J4:J53,"Open")&" | Critical: "&COUNTIF('🚨 AML Alerts'!H4:H53,"Critical"),"") | H9: =IFERROR("Expired: "&COUNTIF('📋 KYC Register'!G4:G53,"Expired")&" | Pending: "&COUNTIF('📋 KYC Register'!G4:G53,"Pending"),"") | K9: =IFERROR("Overdue: "&COUNTIF('🔍 EDD Cases'!O4:O53,"Overdue")&" | Escalated: "&COUNTIF('🔍 EDD Cases'!O4:O53,"Escalated"),"") | N9: High: 11 | Critical: 2 | Q9: =IFERROR(COUNTIF('📋 KYC Register'!N4:N53,"Yes")&" of "&COUNTIF('📋 KYC Register'!F4:F53,"High")&" High Risk","")
B12: 📊 RISK DISTRIBUTION BY CUSTOMER SEGMENT | K12: 📅 MONTHLY ALERT TREND (2024)
B13: Risk Category | C13: Customers | D13: % Share | E13: Alerts | F13: Avg Score | G13: Status | K13: Month | L13: Alerts | M13: SARs | N13: EDD | O13: Closed | P13: Open
B14: Low Risk | C14: =IFERROR(COUNTIF('📋 KYC Register'!F4:F53,"Low"),0) | D14: =IFERROR(C14/COUNTA('📋 KYC Register'!A4:A53),0) | E14: =IFERROR(COUNTIF('🚨 AML Alerts'!H4:H53,"Low"),0) | F14: =IFERROR(AVERAGEIFS('🚨 AML Alerts'!G4:G53,'🚨 AML Alerts'!H4:H53,"Low"),0) | G14: ✅ Normal | K14: Jan | L14: =IFERROR(SUMPRODUCT((TEXT('🚨 AML Alerts'!C4:C53,"MM/YYYY")="01/2024")*('🚨 AML Alerts'!A4:A53<>"")),0) | M14: =IFERROR(SUMPRODUCT((TEXT('📝 SAR Log'!D4:D53,"MM/YYYY")="01/2024")*('📝 SAR Log'!A4:A53<>"")),0) | N14: =IFERROR(SUMPRODUCT((TEXT('🔍 EDD Cases'!E4:E53,"MM/YYYY")="01/2024")*('🔍 EDD Cases'!A4:A53<>"")),0) | O14: =IFERROR(SUMPRODUCT((TEXT('🚨 AML Alerts'!C4:C53,"MM/YYYY")="01/2024")*(('🚨 AML Alerts'!J4:J53="Closed - SAR")+('🚨 AML Alerts'!J4:J53="Closed - No Action"))),0) | P14: =IFERROR(SUMPRODUCT((TEXT('🚨 AML Alerts'!C4:C53,"MM/YYYY")="01/2024")*('🚨 AML Alerts'!J4:J53="Open")),0)
B15: Medium Risk | C15: =IFERROR(COUNTIF('📋 KYC Register'!F4:F53,"Medium"),0) | D15: =IFERROR(C15/COUNTA('📋 KYC Register'!A4:A53),0) | E15: =IFERROR(COUNTIF('🚨 AML Alerts'!H4:H53,"Medium"),0) | F15: =IFERROR(AVERAGEIFS('🚨 AML Alerts'!G4:G53,'🚨 AML Alerts'!H4:H53,"Medium"),0) | G15: ⚠️ Watch | K15: Feb | L15: =IFERROR(SUMPRODUCT((TEXT('🚨 AML Alerts'!C4:C53,"MM/YYYY")="02/2024")*('🚨 AML Alerts'!A4:A53<>"")),0) | M15: =IFERROR(SUMPRODUCT((TEXT('📝 SAR Log'!D4:D53,"MM/YYYY")="02/2024")*('📝 SAR Log'!A4:A53<>"")),0) | N15: =IFERROR(SUMPRODUCT((TEXT('🔍 EDD Cases'!E4:E53,"MM/YYYY")="02/2024")*('🔍 EDD Cases'!A4:A53<>"")),0) | O15: =IFERROR(SUMPRODUCT((TEXT('🚨 AML Alerts'!C4:C53,"MM/YYYY")="02/2024")*(('🚨 AML Alerts'!J4:J53="Closed - SAR")+('🚨 AML Alerts'!J4:J53="Closed - No Action"))),0) | P15: =IFERROR(SUMPRODUCT((TEXT('🚨 AML Alerts'!C4:C53,"MM/YYYY")="02/2024")*('🚨 AML Alerts'!J4:J53="Open")),0)
B16: High Risk | C16: =IFERROR(COUNTIF('📋 KYC Register'!F4:F53,"High"),0) | D16: =IFERROR(C16/COUNTA('📋 KYC Register'!A4:A53),0) | E16: =IFERROR(COUNTIF('🚨 AML Alerts'!H4:H53,"High"),0) | F16: =IFERROR(AVERAGEIFS('🚨 AML Alerts'!G4:G53,'🚨 AML Alerts'!H4:H53,"High"),0) | G16: 🚨 Alert | K16: Mar | L16: =IFERROR(SUMPRODUCT((TEXT('🚨 AML Alerts'!C4:C53,"MM/YYYY")="03/2024")*('🚨 AML Alerts'!A4:A53<>"")),0) | M16: =IFERROR(SUMPRODUCT((TEXT('📝 SAR Log'!D4:D53,"MM/YYYY")="03/2024")*('📝 SAR Log'!A4:A53<>"")),0) | N16: =IFERROR(SUMPRODUCT((TEXT('🔍 EDD Cases'!E4:E53,"MM/YYYY")="03/2024")*('🔍 EDD Cases'!A4:A53<>"")),0) | O16: =IFERROR(SUMPRODUCT((TEXT('🚨 AML Alerts'!C4:C53,"MM/YYYY")="03/2024")*(('🚨 AML Alerts'!J4:J53="Closed - SAR")+('🚨 AML Alerts'!J4:J53="Closed - No Action"))),0) | P16: =IFERROR(SUMPRODUCT((TEXT('🚨 AML Alerts'!C4:C53,"MM/YYYY")="03/2024")*('🚨 AML Alerts'!J4:J53="Open")),0)
B17: PEP | C17: =IFERROR(COUNTIF('📋 KYC Register'!N4:N53,"Yes"),0) | D17: =IFERROR(C17/COUNTA('📋 KYC Register'!A4:A53),0) | E17: =IFERROR(COUNTIF('🚨 AML Alerts'!H4:H53,"Critical"),0) | F17: =IFERROR(AVERAGEIFS('🚨 AML Alerts'!G4:G53,'🚨 AML Alerts'!H4:H53,"Critical"),0) | G17: 👁 Monitor | K17: Apr | L17: =IFERROR(SUMPRODUCT((TEXT('🚨 AML Alerts'!C4:C53,"MM/YYYY")="04/2024")*('🚨 AML Alerts'!A4:A53<>"")),0) | M17: =IFERROR(SUMPRODUCT((TEXT('📝 SAR Log'!D4:D53,"MM/YYYY")="04/2024")*('📝 SAR Log'!A4:A53<>"")),0) | N17: =IFERROR(SUMPRODUCT((TEXT('🔍 EDD Cases'!E4:E53,"MM/YYYY")="04/2024")*('🔍 EDD Cases'!A4:A53<>"")),0) | O17: =IFERROR(SUMPRODUCT((TEXT('🚨 AML Alerts'!C4:C53,"MM/YYYY")="04/2024")*(('🚨 AML Alerts'!J4:J53="Closed - SAR")+('🚨 AML Alerts'!J4:J53="Closed - No Action"))),0) | P17: =IFERROR(SUMPRODUCT((TEXT('🚨 AML Alerts'!C4:C53,"MM/YYYY")="04/2024")*('🚨 AML Alerts'!J4:J53="Open")),0)
B18: Sanctioned | C18: =IFERROR(COUNTIF('📋 KYC Register'!O4:O53,"Fail"),0) | D18: =IFERROR(C18/COUNTA('📋 KYC Register'!A4:A53),0) | E18: =IFERROR(COUNTIF('📝 SAR Log'!N4:N53,"Critical"),0) | F18: =IFERROR(AVERAGEIF('🚨 AML Alerts'!H4:H53,"Critical",'🚨 AML Alerts'!G4:G53),0) | G18: 🔴 Block | K18: May | L18: =IFERROR(SUMPRODUCT((TEXT('🚨 AML Alerts'!C4:C53,"MM/YYYY")="05/2024")*('🚨 AML Alerts'!A4:A53<>"")),0) | M18: =IFERROR(SUMPRODUCT((TEXT('📝 SAR Log'!D4:D53,"MM/YYYY")="05/2024")*('📝 SAR Log'!A4:A53<>"")),0) | N18: =IFERROR(SUMPRODUCT((TEXT('🔍 EDD Cases'!E4:E53,"MM/YYYY")="05/2024")*('🔍 EDD Cases'!A4:A53<>"")),0) | O18: =IFERROR(SUMPRODUCT((TEXT('🚨 AML Alerts'!C4:C53,"MM/YYYY")="05/2024")*(('🚨 AML Alerts'!J4:J53="Closed - SAR")+('🚨 AML Alerts'!J4:J53="Closed - No Action"))),0) | P18: =IFERROR(SUMPRODUCT((TEXT('🚨 AML Alerts'!C4:C53,"MM/YYYY")="05/2024")*('🚨 AML Alerts'!J4:J53="Open")),0)
B19: Under Review | C19: =IFERROR(COUNTIF('📋 KYC Register'!G4:G53,"Under Review"),0) | D19: =IFERROR(C19/COUNTA('📋 KYC Register'!A4:A53),0) | E19: =IFERROR(COUNTIF('🚨 AML Alerts'!J4:J53,"Under Review"),0) | F19: =IFERROR(AVERAGEIF('🚨 AML Alerts'!J4:J53,"Under Review",'🚨 AML Alerts'!G4:G53),0) | G19: 🔄 Review | K19: Jun | L19: =IFERROR(SUMPRODUCT((TEXT('🚨 AML Alerts'!C4:C53,"MM/YYYY")="06/2024")*('🚨 AML Alerts'!A4:A53<>"")),0) | M19: =IFERROR(SUMPRODUCT((TEXT('📝 SAR Log'!D4:D53,"MM/YYYY")="06/2024")*('📝 SAR Log'!A4:A53<>"")),0) | N19: =IFERROR(SUMPRODUCT((TEXT('🔍 EDD Cases'!E4:E53,"MM/YYYY")="06/2024")*('🔍 EDD Cases'!A4:A53<>"")),0) | O19: =IFERROR(SUMPRODUCT((TEXT('🚨 AML Alerts'!C4:C53,"MM/YYYY")="06/2024")*(('🚨 AML Alerts'!J4:J53="Closed - SAR")+('🚨 AML Alerts'!J4:J53="Closed - No Action"))),0) | P19: =IFERROR(SUMPRODUCT((TEXT('🚨 AML Alerts'!C4:C53,"MM/YYYY")="06/2024")*('🚨 AML Alerts'!J4:J53="Open")),0)
K20: Jul | L20: =IFERROR(SUMPRODUCT((TEXT('🚨 AML Alerts'!C4:C53,"MM/YYYY")="07/2024")*('🚨 AML Alerts'!A4:A53<>"")),0) | M20: =IFERROR(SUMPRODUCT((TEXT('📝 SAR Log'!D4:D53,"MM/YYYY")="07/2024")*('📝 SAR Log'!A4:A53<>"")),0) | N20: =IFERROR(SUMPRODUCT((TEXT('🔍 EDD Cases'!E4:E53,"MM/YYYY")="07/2024")*('🔍 EDD Cases'!A4:A53<>"")),0) | O20: =IFERROR(SUMPRODUCT((TEXT('🚨 AML Alerts'!C4:C53,"MM/YYYY")="07/2024")*(('🚨 AML Alerts'!J4:J53="Closed - SAR")+('🚨 AML Alerts'!J4:J53="Closed - No Action"))),0) | P20: =IFERROR(SUMPRODUCT((TEXT('🚨 AML Alerts'!C4:C53,"MM/YYYY")="07/2024")*('🚨 AML Alerts'!J4:J53="Open")),0)
K21: Aug | L21: =IFERROR(SUMPRODUCT((TEXT('🚨 AML Alerts'!C4:C53,"MM/YYYY")="08/2024")*('🚨 AML Alerts'!A4:A53<>"")),0) | M21: =IFERROR(SUMPRODUCT((TEXT('📝 SAR Log'!D4:D53,"MM/YYYY")="08/2024")*('📝 SAR Log'!A4:A53<>"")),0) | N21: =IFERROR(SUMPRODUCT((TEXT('🔍 EDD Cases'!E4:E53,"MM/YYYY")="08/2024")*('🔍 EDD Cases'!A4:A53<>"")),0) | O21: =IFERROR(SUMPRODUCT((TEXT('🚨 AML Alerts'!C4:C53,"MM/YYYY")="08/2024")*(('🚨 AML Alerts'!J4:J53="Closed - SAR")+('🚨 AML Alerts'!J4:J53="Closed - No Action"))),0) | P21: =IFERROR(SUMPRODUCT((TEXT('🚨 AML Alerts'!C4:C53,"MM/YYYY")="08/2024")*('🚨 AML Alerts'!J4:J53="Open")),0)
K22: Sep | L22: =IFERROR(SUMPRODUCT((TEXT('🚨 AML Alerts'!C4:C53,"MM/YYYY")="09/2024")*('🚨 AML Alerts'!A4:A53<>"")),0) | M22: =IFERROR(SUMPRODUCT((TEXT('📝 SAR Log'!D4:D53,"MM/YYYY")="09/2024")*('📝 SAR Log'!A4:A53<>"")),0) | N22: =IFERROR(SUMPRODUCT((TEXT('🔍 EDD Cases'!E4:E53,"MM/YYYY")="09/2024")*('🔍 EDD Cases'!A4:A53<>"")),0) | O22: =IFERROR(SUMPRODUCT((TEXT('🚨 AML Alerts'!C4:C53,"MM/YYYY")="09/2024")*(('🚨 AML Alerts'!J4:J53="Closed - SAR")+('🚨 AML Alerts'!J4:J53="Closed - No Action"))),0) | P22: =IFERROR(SUMPRODUCT((TEXT('🚨 AML Alerts'!C4:C53,"MM/YYYY")="09/2024")*('🚨 AML Alerts'!J4:J53="Open")),0)
K23: Oct | L23: =IFERROR(SUMPRODUCT((TEXT('🚨 AML Alerts'!C4:C53,"MM/YYYY")="10/2024")*('🚨 AML Alerts'!A4:A53<>"")),0) | M23: =IFERROR(SUMPRODUCT((TEXT('📝 SAR Log'!D4:D53,"MM/YYYY")="10/2024")*('📝 SAR Log'!A4:A53<>"")),0) | N23: =IFERROR(SUMPRODUCT((TEXT('🔍 EDD Cases'!E4:E53,"MM/YYYY")="10/2024")*('🔍 EDD Cases'!A4:A53<>"")),0) | O23: =IFERROR(SUMPRODUCT((TEXT('🚨 AML Alerts'!C4:C53,"MM/YYYY")="10/2024")*(('🚨 AML Alerts'!J4:J53="Closed - SAR")+('🚨 AML Alerts'!J4:J53="Closed - No Action"))),0) | P23: =IFERROR(SUMPRODUCT((TEXT('🚨 AML Alerts'!C4:C53,"MM/YYYY")="10/2024")*('🚨 AML Alerts'!J4:J53="Open")),0)
K24: Nov | L24: =IFERROR(SUMPRODUCT((TEXT('🚨 AML Alerts'!C4:C53,"MM/YYYY")="11/2024")*('🚨 AML Alerts'!A4:A53<>"")),0) | M24: =IFERROR(SUMPRODUCT((TEXT('📝 SAR Log'!D4:D53,"MM/YYYY")="11/2024")*('📝 SAR Log'!A4:A53<>"")),0) | N24: =IFERROR(SUMPRODUCT((TEXT('🔍 EDD Cases'!E4:E53,"MM/YYYY")="11/2024")*('🔍 EDD Cases'!A4:A53<>"")),0) | O24: =IFERROR(SUMPRODUCT((TEXT('🚨 AML Alerts'!C4:C53,"MM/YYYY")="11/2024")*(('🚨 AML Alerts'!J4:J53="Closed - SAR")+('🚨 AML Alerts'!J4:J53="Closed - No Action"))),0) | P24: =IFERROR(SUMPRODUCT((TEXT('🚨 AML Alerts'!C4:C53,"MM/YYYY")="11/2024")*('🚨 AML Alerts'!J4:J53="Open")),0)
K25: Dec | L25: =IFERROR(SUMPRODUCT((TEXT('🚨 AML Alerts'!C4:C53,"MM/YYYY")="12/2024")*('🚨 AML Alerts'!A4:A53<>"")),0) | M25: =IFERROR(SUMPRODUCT((TEXT('📝 SAR Log'!D4:D53,"MM/YYYY")="12/2024")*('📝 SAR Log'!A4:A53<>"")),0) | N25: =IFERROR(SUMPRODUCT((TEXT('🔍 EDD Cases'!E4:E53,"MM/YYYY")="12/2024")*('🔍 EDD Cases'!A4:A53<>"")),0) | O25: =IFERROR(SUMPRODUCT((TEXT('🚨 AML Alerts'!C4:C53,"MM/YYYY")="12/2024")*(('🚨 AML Alerts'!J4:J53="Closed - SAR")+('🚨 AML Alerts'!J4:J53="Closed - No Action"))),0) | P25: =IFERROR(SUMPRODUCT((TEXT('🚨 AML Alerts'!C4:C53,"MM/YYYY")="12/2024")*('🚨 AML Alerts'!J4:J53="Open")),0)

Sheet 📋 KYC Register
A1: KYC CUSTOMER REGISTER | 50 Customer Records
A2: Know Your Customer — Identification, Verification & Risk Classification
A3: Cust ID | B3: Full Name | C3: DOB | D3: Nationality | E3: Account Type | F3: Risk Level | G3: KYC Status | H3: ID Type | I3: ID Number | J3: Expiry Date | K3: Onboard Date | L3: Last Review | M3: Next Review | N3: PEP Flag | O3: Sanctions Check | P3: Remarks
A4: CUST10001 | B4: Ahmed Al-Rashid | C4: 01/01/1960 | D4: UAE | E4: Individual | F4: Low | G4: Verified | H4: Passport | I4: XX200000 | J4: 28/01/2025 | K4: 01/01/2018 | L4: 01/01/2019 | M4: 01/01/2020 | N4: No | O4: Pass | P4: Active
A5: CUST10002 | B5: Priya Sharma | C5: 02/02/1961 | D5: India | E5: Corporate | F5: Low | G5: Expired | H5: NID | I5: XX200007 | J5: 28/02/2026 | K5: 02/02/2019 | L5: 02/02/2020 | M5: 01/02/2021 | N5: No | O5: Pass | P5: Active
A6: CUST10003 | B6: John O'Brien | C6: 03/03/1962 | D6: Ireland | E6: SME | F6: Medium | G6: Under Review | H6: NRIC | I6: XX200014 | J6: 28/03/2027 | K6: 03/03/2020 | L6: 03/03/2021 | M6: 03/03/2022 | N6: No | O6: Pass | P6: Active
A7: CUST10004 | B7: Liu Wei | C7: 04/04/1963 | D7: China | E7: Joint | F7: Low | G7: Verified | H7: CPF | I7: XX200021 | J7: 28/04/2028 | K7: 04/04/2021 | L7: 04/04/2022 | M7: 04/04/2023 | N7: No | O7: Pass | P7: Docs Pending
A8: CUST10005 | B8: Fatima Al-Zahra | C8: 05/05/1964 | D8: Saudi Arabia | E8: Trust | F8: High | G8: Verified | H8: My Number | I8: XX200028 | J8: 28/05/2025 | K8: 05/05/2022 | L8: 05/05/2023 | M8: 04/05/2024 | N8: Yes | O8: Fail | P8: Flagged against sanctions list – under review
A9: CUST10006 | B9: Carlos Mendez | C9: 06/06/1965 | D9: Mexico | E9: Individual | F9: Medium | G9: Verified | H9: CI | I9: XX200035 | J9: 28/06/2026 | K9: 06/06/2023 | L9: 05/06/2024 | M9: 05/06/2025 | N9: No | O9: Pass | P9: Suspended
A10: CUST10007 | B10: Anna Kowalski | C10: 07/07/1966 | D10: Poland | E10: Corporate | F10: Low | G10: Expired | H10: Driver's Licence | I10: XX200042 | J10: 28/07/2027 | K10: 07/07/2018 | L10: 07/07/2019 | M10: 06/07/2020 | N10: No | O10: Pass | P10: Monitoring
A11: CUST10008 | B11: Raj Patel | C11: 08/08/1967 | D11: India | E11: SME | F11: Low | G11: Verified | H11: Aadhaar | I11: XX200049 | J11: 28/08/2028 | K11: 08/08/2019 | L11: 07/08/2020 | M11: 07/08/2021 | N11: Yes | O11: Pass | P11: Active
A12: CUST10009 | B12: Sophie Dubois | C12: 09/09/1968 | D12: France | E12: Joint | F12: Medium | G12: Under Review | H12: Passport | I12: XX200056 | J12: 28/09/2025 | K12: 09/09/2020 | L12: 09/09/2021 | M12: 09/09/2022 | N12: No | O12: Pass | P12: Active
A13: CUST10010 | B13: Omar Hassan | C13: 10/10/1969 | D13: Egypt | E13: Trust | F13: High | G13: Verified | H13: NID | I13: XX200063 | J13: 28/10/2026 | K13: 10/10/2021 | L13: 10/10/2022 | M13: 10/10/2023 | N13: No | O13: Fail | P13: Flagged against sanctions list – under review
A14: CUST10011 | B14: Elena Ivanova | C14: 11/11/1970 | D14: Russia | E14: Individual | F14: Medium | G14: Verified | H14: NRIC | I14: XX200070 | J14: 28/11/2027 | K14: 11/11/2022 | L14: 11/11/2023 | M14: 10/11/2024 | N14: No | O14: Pass | P14: Docs Pending
... A53: CUST10050 | B53: Olga Koroleva | C53: 22/02/1969 | D53: Russia | E53: Trust | F53: Medium | G53: Verified | H53: NID | I53: XX200343 | J53: 28/02/2026 | K53: 22/02/2019 | L53: 22/02/2020 | M53: 21/02/2021 | N53: No | O53: Pass | P53: Active
A56: KYC STATUS SUMMARY (50 customers)
A57: Verified | D57: =COUNTIF(G4:G53,"Verified")
A58: Pending | D58: =COUNTIF(G4:G53,"Pending")
A59: Under Review | D59: =COUNTIF(G4:G53,"Under Review")
A60: Expired | D60: =COUNTIF(G4:G53,"Expired")
A61: PEP Customers | D61: =COUNTIF(N4:N53,"Yes")
A62: Sanctions Fail | D62: =COUNTIF(O4:O53,"Fail")

Sheet 🚨 AML Alerts
A1: AML ALERT MANAGEMENT | 50 Alert Records
A2: Suspicious Transaction Alerts — Detection, Investigation & Disposition
A3: Alert ID | B3: Cust ID | C3: Alert Date | D3: Alert Type | E3: Transaction Amt | F3: Currency | G3: Risk Score | H3: Priority | I3: Assigned To | J3: Status | K3: Days Open | L3: Investigation Notes | M3: SAR Filed | N3: Resolution | O3: Closed Date
A4: ALT20001 | B4: CUST10001 | C4: 07/01/2024 | D4: Structuring | E4: 100000 | F4: USD | G4: 84 | H4: High | I4: A. Kumar | J4: Open | K4: 884 | L4: Reviewing transaction pattern | M4: No | N4: Pending
A5: ALT20002 | B5: CUST10002 | C5: 10/02/2024 | D5: Unusual Wire Transfer | E5: 55000 | F5: EUR | G5: 87 | H5: High | I5: S. Patel | J5: Under Review | K5: 852 | L5: Documentation requested from customer | M5: No | N5: In Progress
A6: ALT20003 | B6: CUST10003 | C6: 13/02/2024 | D6: Cash Threshold | E6: 6000 | F6: GBP | G6: 61 | H6: Medium | I6: M. Ali | J6: Escalated | K6: 822 | L6: Escalated to MLRO for decision | M6: No | N6: SAR Filed
A7: ALT20004 | B7: CUST10004 | C7: 21/02/2024 | D7: Rapid Movement | E7: 6000 | F7: AED | G7: 93 | H7: High | I7: R. Chen | J7: Closed - SAR | K7: 27 | L7: SAR filed to FIU — awaiting feedback | M7: Yes | N7: Case Closed | O7: 09/03/2024
A8: ALT20005 | B8: CUST10005 | C8: 22/02/2024 | D8: Dormant Reactivation | E8: 12500 | F8: INR | G8: 65 | H8: Medium | I8: J. Smith | J8: Closed - No Action | K8: 5 | L8: Normal business activity confirmed | M8: No | N8: No Action Required | O8: 10/03/2024
A9: ALT20006 | B9: CUST10006 | C9: 24/02/2024 | D9: High-Risk Jurisdiction | E9: 200000 | F9: SGD | G9: 86 | H9: High | I9: L. Wang | J9: Pending Info | K9: 727 | L9: Awaiting customer response to query | M9: No | N9: Pending Documents
A10: ALT20007 | B10: CUST10007 | C10: 28/02/2024 | D10: PEP Transaction | E10: 48500 | F10: USD | G10: 78 | H10: Critical | I10: P. Nair | J10: Critical - Escalated | K10: 696 | L10: PEP ongoing verification | M10: No | N10: Referred to Authorities
A11: ALT20008 | B11: CUST10008 | C11: 22/03/2024 | D11: Sanctions Match | E11: 150000 | F11: EUR | G11: 58 | H11: Critical | I11: F. Ahmed | J11: Open | K11: 664 | L11: Sanctions list cross-checked | M11: No | N11: Cleared
A12: ALT20009 | B12: CUST10009 | C12: 24/03/2024 | D12: Round-Dollar Amounts | E12: 110000 | F12: GBP | G12: 60 | H12: Medium | I12: T. Obi | J12: Under Review | K12: 632 | L12: Pattern analysis completed | M12: No | N12: SAR Submitted
A13: ALT20010 | B13: CUST10010 | C13: 10/04/2024 | D13: Velocity Alert | E13: 175000 | F13: AED | G13: 59 | H13: Low | I13: Head AML | J13: Escalated | K13: 601 | L13: New alert raised — monitoring | M13: No | N13: Monitoring
A14: ALT20011 | B14: CUST10011 | C14: 16/04/2024 | D14: Layering | E14: 175000 | F14: INR | G14: 90 | H14: High | I14: A. Kumar | J14: Closed - SAR | K14: 5 | L14: Unusual cross-border movement | M14: Yes | N14: Pending | O14: 10/05/2024
A15: ALT20012 | B15: CUST10012 | C15: 24/04/2024 | D15: Integration | E15: 6000 | F15: SGD | G15: 93 | H15: High | I15: S. Patel | J15: Closed - No Action | K15: 9 | L15: Cash deposits inconsistent with profile | M15: Yes | N15: In Progress | O15: 13/05/2024
A16: ALT20013 | B16: CUST10013 | C16: 02/05/2024 | D16: Smurfing | E16: 32000 | F16: USD | G16: 89 | H16: Medium | I16: M. Ali | J16: Pending Info | K16: 872 | L16: Wire transfer to high-risk jurisdiction | M16: No | N16: SAR Filed
A17: ALT20014 | B17: CUST10014 | C17: 07/05/2024 | D17: Cyber Fraud | E17: 8500 | F17: EUR | G17: 80 | H17: High | I17: R. Chen | J17: Critical - Escalated | K17: 840 | L17: Round-tripping detected | M17: No | N17: Case Closed
A18: ALT20015 | B18: CUST10015 | C18: 15/05/2024 | D18: Tax Evasion Indicator | E18: 42000 | F18: GBP | G18: 88 | H18: Medium | I18: J. Smith | J18: Open | K18: 810 | L18: Beneficial owner not confirmed | M18: Yes | N18: No Action Required
A19: ALT20016 | B19: CUST10016 | C19: 20/05/2024 | D19: Structuring | E19: 48500 | F19: AED | G19: 70 | H19: High | I19: L. Wang | J19: Under Review | K19: 778 | L19: Reviewing transaction pattern | M19: No | N19: Pending Documents
A20: ALT20017 | B20: CUST10017 | C20: 21/05/2024 | D20: Unusual Wire Transfer | E20: 24500 | F20: INR | G20: 76 | H20: Critical | I20: P. Nair | J20: Escalated | K20: 747 | L20: Documentation requested from customer | M20: No | N20: Referred to Authorities
A21: ALT20018 | B21: CUST10018 | C21: 05/06/2024 | D21: Cash Threshold | E21: 95000 | F21: SGD | G21: 69 | H21: Critical | I21: F. Ahmed | J21: Closed - SAR | K21: 19 | L21: Escalated to MLRO for decision | M21: Yes | N21: Cleared | O21: 26/06/2024
A22: ALT20019 | B22: CUST10019 | C22: 07/06/2024 | D22: Rapid Movement | E22: 9999 | F22: USD | G22: 59 | H22: Medium | I22: T. Obi | J22: Closed - No Action | K22: 8 | L22: SAR filed to FIU — awaiting feedback | M22: No | N22: SAR Submitted | O22: 20/06/2024
A23: ALT20020 | B23: CUST10020 | C23: 09/06/2024 | D23: Dormant Reactivation | E23: 24500 | F23: EUR | G23: 57 | H23: Low | I23: Head AML | J23: Pending Info | K23: 652 | L23: Normal business activity confirmed | M23: No | N23: Monitoring
A24: ALT20021 | B24: CUST10021 | C24: 03/07/2024 | D24: High-Risk Jurisdiction | E24: 24500 | F24: GBP | G24: 87 | H24: High | I24: A. Kumar | J24: Critical - Escalated | K24: 620 | L24: Awaiting customer response to query | M24: No | N24: Pending
A25: ALT20022 | B25: CUST10022 | C25: 09/07/2024 | D25: PEP Transaction | E25: 55000 | F25: AED | G25: 97 | H25: High | I25: S. Patel | J25: Open | K25: 589 | L25: PEP ongoing verification | M25: Yes | N25: In Progress
A26: ALT20023 | B26: CUST10023 | C26: 21/07/2024 | D26: Sanctions Match | E26: 32000 | F26: INR | G26: 89 | H26: Medium | I26: M. Ali | J26: Under Review | K26: 557 | L26: Sanctions list cross-checked | M26: No | N26: SAR Filed
A27: ALT20024 | B27: CUST10024 | C27: 03/08/2024 | D27: Round-Dollar Amounts | E27: 110000 | F27: SGD | G27: 91 | H27: High | I27: R. Chen | J27: Escalated | K27: 526 | L27: Pattern analysis completed | M27: Yes | N27: Case Closed
A28: ALT20025 | B28: CUST10025 | C28: 04/08/2024 | D28: Velocity Alert | E28: 175000 | F28: USD | G28: 81 | H28: Medium | I28: J. Smith | J28: Closed - SAR | K28: 8 | L28: New alert raised — monitoring | M28: Yes | N28: No Action Required | O28: 26/08/2024
A29: ALT20026 | B29: CUST10026 | C29: 09/08/2024 | D29: Layering | E29: 48500 | F29: EUR | G29: 97 | H29: High | I29: L. Wang | J29: Closed - No Action | K29: 4 | L29: Unusual cross-border movement | M29: Yes | N29: Pending Documents | O29: 14/08/2024
A30: ALT20027 | B30: CUST10027 | C30: 01/09/2024 | D30: Integration | E30: 88000 | F30: GBP | G30: 81 | H30: Critical | I30: P. Nair | J30: Pending Info | K30: 798 | L30: Cash deposits inconsistent with profile | M30: Yes | N30: Referred to Authorities
A31: ALT20028 | B31: CUST10028 | C31: 02/09/2024 | D31: Smurfing | E31: 15000 | F31: AED | G31: 98 | H31: Critical | I31: F. Ahmed | J31: Critical - Escalated | K31: 766 | L31: Wire transfer to high-risk jurisdiction | M31: No | N31: Cleared
A32: ALT20029 | B32: CUST10029 | C32: 08/09/2024 | D32: Cyber Fraud | E32: 15000 | F32: INR | G32: 80 | H32: Medium | I32: T. Obi | J32: Open | K32: 763 | L32: Round-tripping detected | M32: No | N32: SAR Submitted
A33: ALT20030 | B33: CUST10030 | C33: 09/09/2024 | D33: Tax Evasion Indicator | E33: 48500 | F33: SGD | G33: 70 | H33: Low | I33: Head AML | J33: Under Review | K33: 731 | L33: Beneficial owner not confirmed | M33: No | N33: Monitoring
A34: ALT20031 | B34: CUST10031 | C34: 23/09/2024 | D34: Structuring | E34: 32000 | F34: USD | G34: 89 | H34: High | I34: A. Kumar | J34: Escalated | K34: 700 | L34: Reviewing transaction pattern | M34: Yes | N34: Pending
A35: ALT20032 | B35: CUST10032 | C35: 08/10/2024 | D35: Unusual Wire Transfer | E35: 88000 | F35: EUR | G35: 66 | H35: High | I35: S. Patel | J35: Closed - SAR | K35: 5 | L35: Documentation requested from customer | M35: Yes | N35: In Progress | O35: 16/10/2024
A36: ALT20033 | B36: CUST10033 | C36: 11/10/2024 | D36: Cash Threshold | E36: 150000 | F36: GBP | G36: 59 | H36: Medium | I36: M. Ali | J36: Closed - No Action | K36: 15 | L36: Escalated to MLRO for decision | M36: Yes | N36: SAR Filed | O36: 02/11/2024
A37: ALT20034 | B37: CUST10034 | C37: 14/10/2024 | D37: Rapid Movement | E37: 95000 | F37: AED | G37: 61 | H37: High | I37: R. Chen | J37: Pending Info | K37: 605 | L37: SAR filed to FIU — awaiting feedback | M37: No | N37: Case Closed
A38: ALT20035 | B38: CUST10035 | C38: 23/10/2024 | D38: Dormant Reactivation | E38: 95000 | F38: INR | G38: 55 | H38: Medium | I38: J. Smith | J38: Critical - Escalated | K38: 573 | L38: Normal business activity confirmed | M38: No | N38: No Action Required
A39: ALT20036 | B39: CUST10036 | C39: 27/10/2024 | D39: High-Risk Jurisdiction | E39: 150000 | F39: SGD | G39: 65 | H39: High | I39: L. Wang | J39: Open | K39: 542 | L39: Awaiting customer response to query | M39: Yes | N39: Pending Documents
A40: ALT20037 | B40: CUST10037 | C40: 28/10/2024 | D40: PEP Transaction | E40: 175000 | F40: USD | G40: 85 | H40: Critical | I40: P. Nair | J40: Under Review | K40: 876 | L40: PEP ongoing verification | M40: No | N40: Referred to Authorities
...

Sheet 🔍 EDD Cases
A1: ENHANCED DUE DILIGENCE (EDD) CASE MANAGEMENT | 50 Cases
A2: In-depth Review for High-Risk Customers, PEPs & Complex Structures
A3: Case ID | B3: Cust ID | C3: Customer Name | D3: EDD Reason | E3: Open Date | F3: Due Date | G3: Investigator | H3: Stage | I3: UBO Verified | J3: Source of Funds | K3: Net Worth ($K) | L3: Risk Rating | M3: Docs Collected | N3: Actions Required | O3: Status
A4: EDD30001 | B4: CUST10001 | C4: Ahmed Al-Rashid | D4: PEP Customer | E4: 13/07/2024 | F4: 08/08/2024 | G4: A. Kumar | H4: Initial Review | I4: Yes | J4: Business Revenue | K4: 380 | L4: High | M4: 7/10 | N4: Verify UBO chain | O4: Open
A5: EDD30002 | B5: CUST10002 | C5: Priya Sharma | D5: High Net Worth | E5: 08/03/2024 | F5: 06/04/2024 | G5: S. Patel | H5: Document Collection | I5: No | J5: Inheritance | K5: 650 | L5: Very High | M5: 5/10 | N5: Request 3yr bank statements | O5: In Progress
A6: EDD30003 | B6: CUST10003 | C6: John O'Brien | D6: Cross-Border Transactions | E6: 25/03/2024 | F6: 13/04/2024 | G6: M. Ali | H6: UBO Analysis | I6: Partial | J6: Investment | K6: 1500 | L6: High | M6: 5/10 | N6: Obtain tax records | O6: Overdue
A7: EDD30004 | B7: CUST10004 | C7: Liu Wei | D7: Complex Ownership | E7: 24/05/2024 | F7: 01/07/2024 | G7: R. Chen | H7: Source of Funds Verification | I7: Yes | J7: Employment | K7: 650 | L7: Medium-High | M7: 8/10 | N7: Confirm business license | O7: Completed
A8: EDD30005 | B8: CUST10005 | C8: Fatima Al-Zahra | D8: Sanctions Adjacent | E8: 22/09/2024 | F8: 11/10/2024 | G8: J. Smith | H8: Risk Assessment | I8: No | J8: Property Sale | K8: 1800 | L8: Very High | M8: 6/10 | N8: Review corporate structure | O8: Escalated
A9: EDD30006 | B9: CUST10006 | C9: Carlos Mendez | D9: Unusual Business Model | E9: 07/08/2024 | F9: 16/09/2024 | G9: L. Wang | H9: Senior Approval | I9: Partial | J9: Pension | K9: 900 | L9: High | M9: 7/10 | N9: Check adverse media | O9: Pending Docs
A10: EDD30007 | B10: CUST10007 | C10: Anna Kowalski | D10: High-Risk Country | E10: 26/04/2024 | F10: 02/06/2024 | G10: P. Nair | H10: Completed | I10: Yes | J10: Trade Income | K10: 750 | L10: Medium-High | M10: 2/10 | N10: Obtain wealth declaration | O10: Open
A11: EDD30008 | B11: CUST10008 | C11: Raj Patel | D11: Cash Intensive | E11: 28/07/2024 | F11: 24/08/2024 | G11: F. Ahmed | H11: Ongoing Monitoring | I11: No | J11: Unknown | K11: 900 | L11: High | M11: 3/10 | N11: Verify source of funds | O11: In Progress
A12: EDD30009 | B12: CUST10009 | C12: Sophie Dubois | D12: Prior SAR | E12: 15/03/2024 | F12: 09/04/2024 | G12: T. Obi | H12: Initial Review | I12: Partial | J12: Remittance | K12: 750 | L12: Very High | M12: 5/10 | N12: None — case complete | O12: Overdue
A13: EDD30010 | B13: CUST10010 | C13: Omar Hassan | D13: Adverse Media | E13: 03/06/2024 | F13: 22/06/2024 | G13: Head AML | H13: Document Collection | I13: Yes | J13: Loan Proceeds | K13: 6000 | L13: Medium | M13: 6/10 | N13: Escalate to MLRO | O13: Completed
A14: EDD30011 | B14: CUST10011 | C14: Elena Ivanova | D14: PEP Customer | E14: 11/08/2024 | F14: 19/09/2024 | G14: A. Kumar | H14: UBO Analysis | I14: No | J14: Business Revenue | K14: 1800 | L14: High | M14: 7/10 | N14: Obtain board resolution | O14: Escalated
A15: EDD30012 | B15: CUST10012 | C15: Michael Chen | D15: High Net Worth | E15: 09/01/2024 | F15: 23/01/2024 | G15: S. Patel | H15: Source of Funds Verification | I15: Partial | J15: Inheritance | K15: 750 | L15: Very High | M15: 5/10 | N15: Verify property ownership | O15: Pending Docs
... A53: EDD30050 | B53: CUST10050 | C53: Olga Koroleva | D53: Adverse Media | E53: 13/05/2024 | F53: 24/06/2024 | G53: Head AML | H53: Document Collection | I53: No | J53: Loan Proceeds | K53: 1100 | L53: Medium | M53: 5/10 | N53: Review corporate structure | O53: In Progress

Sheet 📝 SAR Log
A1: SUSPICIOUS ACTIVITY REPORT (SAR) LOG | 50 SAR Records
A2: Official Record of All SARs Filed to Financial Intelligence Unit (FIU)
A3: SAR Ref | B3: Alert ID | C3: Cust ID | D3: Filing Date | E3: Suspicious Activity | F3: Amount | G3: Currency | H3: Filed By | I3: MLRO Approved | J3: FIU Reference | K3: Feedback Received | L3: Case Outcome | M3: SAR Type | N3: Priority | O3: Remarks
A4: SAR/2024/1001 | B4: ALT20004 | C4: CUST10004 | D4: 12/11/2024 | E4: PEP misuse of business account | F4: 190000 | G4: AED | H4: R. Chen | I4: Yes | J4: FIU/2024/5004 | K4: Received | L4: No Further Action | M4: Voluntary Disclosure | N4: High | O4: FIU acknowledged
A5: SAR/2024/1002 | B5: ALT20011 | C5: CUST10011 | D5: 08/12/2024 | E5: Rapid in/out wire movements | F5: 67000 | G5: INR | H5: A. Kumar | I5: Yes | J5: FIU/2024/5011 | K5: Pending | L5: Acquitted | M5: STR | N5: High | O5: Charged
A6: SAR/2024/1003 | B6: ALT20012 | C6: CUST10012 | D6: 28/07/2024 | E6: Shell company transactions | F6: 78000 | G6: SGD | H6: S. Patel | I6: Yes | J6: FIU/2024/5012 | K6: Received | L6: Convicted | M6: CTR | N6: Critical | O6: Case dismissed
A7: SAR/2024/1004 | B7: ALT20015 | C7: CUST10015 | D7: 17/02/2024 | E7: Undisclosed beneficial owner | F7: 42000 | G7: GBP | H7: J. Smith | I7: Yes | J7: FIU/2024/5015 | K7: No Feedback | L7: Active | M7: Tipping-off Report | N7: Medium | O7: Ongoing
A8: SAR/2024/1005 | B8: ALT20018 | C8: CUST10018 | D8: 22/05/2024 | E8: Layering - Complex inter-bank transfers | F8: 28000 | G8: SGD | H8: F. Ahmed | I8: Yes | J8: FIU/2024/5018 | K8: Received | L8: Prosecution Initiated | M8: SAR | N8: Medium | O8: Referred to Police
A9: SAR/2024/1006 | B9: ALT20022 | C9: CUST10022 | D9: 24/05/2024 | E9: Smurfing - Multiple parties same destination | F9: 89000 | G9: AED | H9: S. Patel | I9: Yes | J9: FIU/2024/5022 | K9: Received | L9: Referred to Police | M9: CTR | N9: Critical | O9: Court proceedings
A10: SAR/2024/1007 | B10: ALT20024 | C10: CUST10024 | D10: 18/08/2024 | E10: Cyber fraud proceeds | F10: 67000 | G10: SGD | H10: R. Chen | I10: Yes | J10: FIU/2024/5024 | K10: Received | L10: Pending Review | M10: Voluntary Disclosure | N10: High | O10: Under review
A11: SAR/2024/1008 | B11: ALT20025 | C11: CUST10025 | D11: 21/09/2024 | E11: Tax evasion indicators | F11: 120000 | G11: USD | H11: J. Smith | I11: Yes | J11: FIU/2024/5025 | K11: Pending | L11: Court Proceedings | M11: Tipping-off Report | N11: Medium | O11: Active investigation
A12: SAR/2024/1009 | B12: ALT20026 | C12: CUST10026 | D12: 25/10/2024 | E12: Rapid in/out wire movements | F12: 230000 | G12: EUR | H12: L. Wang | I12: Yes | J12: FIU/2024/5026 | K12: Received | L12: Acquitted | M12: STR | N12: High | O12: Charged
A13: SAR/2024/1010 | B13: ALT20027 | C13: CUST10027 | D13: 27/11/2024 | E13: Shell company transactions | F13: 260000 | G13: GBP | H13: P. Nair | I13: Yes | J13: FIU/2024/5027 | K13: No Feedback | L13: Convicted | M13: CTR | N13: Critical | O13: Case dismissed
A14: SAR/2024/1011 | B14: ALT20031 | C14: CUST10031 | D14: 03/05/2024 | E14: Structuring - Multiple txns below threshold | F14: 155000 | G14: USD | H14: A. Kumar | I14: Yes | J14: FIU/2024/5031 | K14: Pending | L14: Under Investigation | M14: STR | N14: High | O14: Normal follow-up
A15: SAR/2024/1012 | B15: ALT20032 | C15: CUST10032 | D15: 02/10/2024 | E15: Suspected proceeds of drug trafficking | F15: 260000 | G15: EUR | H15: S. Patel | I15: Yes | J15: FIU/2024/5032 | K15: Received | L15: Case Closed | M15: CTR | N15: Critical | O15: Assets frozen
... A22: SAR/2024/1019 | B22: ALT20050 | C22: CUST10050 | D22: 13/12/2024 | E22: Unusual cash deposits - no business rationale | F22: 28000 | G22: EUR | H22: Head AML | I22: Yes | J22: FIU/2024/5050 | K22: Received | L22: Intelligence Only | M22: Tipping-off Report | N22: Medium | O22: STR also filed

Sheet ⚖️ Risk Matrix
A1: AML / KYC RISK ASSESSMENT MATRIX | Comprehensive Scoring
A2: Inherent Risk × Control Effectiveness = Residual Risk | Risk Appetite: Medium-Low
A3: Risk Factor | B3: Category | C3: Inherent Risk (1-10) | D3: Control Rating (1-10) | E3: Residual Risk | F3: Risk Level | G3: Weight (%) | H3: Weighted Score | I3: Mitigation Action
A4: Customer Identity Verification | B4: KYC | C4: 8 | D4: 7 | E4: =ROUND(C4*(1-D4/10),1) | F4: =IF(E4>=7,"High",IF(E4>=4,"Medium","Low")) | G4: 15 | H4: =E4*G4/100 | I4: Core KYC control — mandatory
A5: PEP Screening | B5: KYC/AML | C5: 9 | D5: 8 | E5: =ROUND(C5*(1-D5/10),1) | F5: =IF(E5>=7,"High",IF(E5>=4,"Medium","Low")) | G5: 12 | H5: =E5*G5/100 | I5: Enhanced monitoring + MLRO approval
A6: Sanctions Screening | B6: AML | C6: 10 | D6: 9 | E6: =ROUND(C6*(1-D6/10),1) | F6: =IF(E6>=7,"High",IF(E6>=4,"Medium","Low")) | G6: 15 | H6: =E6*G6/100 | I6: Real-time screening required
A7: Transaction Monitoring | B7: AML | C7: 8 | D7: 7 | E7: =ROUND(C7*(1-D7/10),1) | F7: =IF(E7>=7,"High",IF(E7>=4,"Medium","Low")) | G7: 12 | H7: =E7*G7/100 | I7: Rule-based + AI anomaly detection
A8: Source of Funds Verification | B8: EDD | C8: 7 | D8: 6 | E8: =ROUND(C8*(1-D8/10),1) | F8: =IF(E8>=7,"High",IF(E8>=4,"Medium","Low")) | G8: 10 | H8: =E8*G8/100 | I8: Documentary evidence mandatory
A9: UBO Identification | B9: EDD/KYC | C9: 8 | D9: 7 | E9: =ROUND(C9*(1-D9/10),1) | F9: =IF(E9>=7,"High",IF(E9>=4,"Medium","Low")) | G9: 10 | H9: =E9*G9/100 | I9: For complex/corporate structures
A10: Geographic Risk Assessment | B10: AML | C10: 7 | D10: 8 | E10: =ROUND(C10*(1-D10/10),1) | F10: =IF(E10>=7,"High",IF(E10>=4,"Medium","Low")) | G10: 8 | H10: =E10*G10/100 | I10: Country risk model — quarterly update
A11: Cash Threshold Monitoring | B11: AML | C11: 6 | D11: 7 | E11: =ROUND(C11*(1-D11/10),1) | F11: =IF(E11>=7,"High",IF(E11>=4,"Medium","Low")) | G11: 8 | H11: =E11*G11/100 | I11: CTR auto-filing above $10,000
A12: Adverse Media Screening | B12: KYC | C12: 7 | D12: 6 | E12: =ROUND(C12*(1-D12/10),1) | F12: =IF(E12>=7,"High",IF(E12>=4,"Medium","Low")) | G12: 5 | H12: =E12*G12/100 | I12: Automated daily + manual quarterly
A13: SAR Filing Timeliness | B13: AML | C13: 8 | D13: 8 | E13: =ROUND(C13*(1-D13/10),1) | F13: =IF(E13>=7,"High",IF(E13>=4,"Medium","Low")) | G13: 5 | H13: =E13*G13/100 | I13: 30-day SLA from detection to filing
A14: Wire Transfer Monitoring | B14: AML | C14: 8 | D14: 7 | E14: =ROUND(C14*(1-D14/10),1) | F14: =IF(E14>=7,"High",IF(E14>=4,"Medium","Low")) | G14: 6 | H14: =E14*G14/100 | I14: SWIFT monitoring — FATF compliance
A15: EDD Review Frequency | B15: EDD | C15: 7 | D15: 7 | E15: =ROUND(C15*(1-D15/10),1) | F15: =IF(E15>=7,"High",IF(E15>=4,"Medium","Low")) | G15: 5 | H15: =E15*G15/100 | I15: Annual for High Risk, biennial for Med
... A18: Regulatory Reporting | B18: Governance | C18: 9 | D18: 8 | E18: =ROUND(C18*(1-D18/10),1) | F18: =IF(E18>=7,"High",IF(E18>=4,"Medium","Low")) | G18: 4 | H18: =E18*G18/100 | I18: Timely CTR/SAR reporting to FIU
A19: COMPOSITE RISK SCORE (Weighted Average) | G19: =SUM(G4:G18) | H19: =SUM(H4:H18)

Sheet 💸 Transaction Monitor
A1: TRANSACTION MONITORING REGISTER | 50 Flagged Transactions
A2: Rule-Based & AI-Triggered Suspicious Transaction Records
A3: Txn ID | B3: Cust ID | C3: Date | D3: Txn Type | E3: Amount | F3: Currency | G3: Counterparty | H3: Country | I3: Rule Triggered | J3: Risk Flag | K3: Reviewed | L3: Action | M3: Reviewer | N3: Date Reviewed
A4: TXN40001 | B4: CUST10001 | C4: 01/01/2024 | D4: Wire Transfer | E4: 48000 | F4: USD | G4: Carlos Mendez | H4: UAE | I4: Amount > $10,000 Cash | J4: High | K4: Yes | L4: Refer to MLRO | M4: A. Kumar | N4: 06/01/2024
A5: TXN40002 | B5: CUST10002 | C5: 02/02/2024 | D5: Cash Deposit | E5: 88000 | F5: EUR | G5: Anna Kowalski | H5: Panama | I5: Rapid in-out same day | J5: Medium | K5: Yes | L5: Contact Customer | M5: S. Patel | N5: 07/02/2024
A6: TXN40003 | B6: CUST10003 | C6: 03/03/2024 | D6: Cash Withdrawal | E6: 95000 | F6: GBP | G6: Raj Patel | H6: British Virgin Islands | I6: High-risk jurisdiction transfer | J6: Low | K6: Yes | L6: Freeze Transaction | M6: M. Ali | N6: 10/03/2024
A7: TXN40004 | B7: CUST10004 | C7: 04/04/2024 | D7: SWIFT Transfer | E7: 67000 | F7: AED | G7: Sophie Dubois | H7: Cayman Islands | I7: Multiple transactions structuring | J7: High | K7: Yes | L7: Ongoing Review | M7: R. Chen | N7: 14/04/2024
A8: TXN40005 | B8: CUST10005 | C8: 05/05/2024 | D8: Internal Transfer | E8: 8500 | F8: USD | G8: Omar Hassan | H8: Switzerland | I8: Dormant account sudden activity | J8: Medium | K8: No | L8: Refer to MLRO | M8: J. Smith
A9: TXN40006 | B9: CUST10006 | C9: 06/06/2024 | D9: Crypto Exchange | E9: 9800 | F9: EUR | G9: Elena Ivanova | H9: Russia | I9: Round-dollar amounts | J9: Low | K9: Yes | L9: Monitor & Watch | M9: L. Wang | N9: 10/06/2024
A10: TXN40007 | B10: CUST10007 | C10: 07/07/2024 | D10: Real Estate Payment | E10: 88000 | F10: GBP | G10: Michael Chen | H10: Nigeria | I10: Velocity threshold breach | J10: High | K10: Pending | L10: Ongoing Review | M10: P. Nair
A11: TXN40008 | B11: CUST10008 | C11: 08/08/2024 | D11: Trade Finance | E11: 200000 | F11: AED | G11: Aisha Bakr | H11: Iran | I11: PEP counterparty | J11: Medium | K11: No | L11: Block & Report | M11: F. Ahmed
A12: TXN40009 | B12: CUST10009 | C12: 09/09/2024 | D12: Card Transaction | E12: 42000 | F12: USD | G12: Pedro Alves | H12: North Korea | I12: Sanctions list match | J12: Low | K12: Yes | L12: Refer to MLRO | M12: T. Obi | N12: 17/09/2024
A13: TXN40010 | B13: CUST10010 | C13: 10/10/2024 | D13: Loan Drawdown | E13: 100000 | F13: EUR | G13: Nadia Petrova | H13: Myanmar | I13: Unusual frequency pattern | J13: High | K13: Yes | L13: Monitor & Watch | M13: Head AML | N13: 19/10/2024
A14: TXN40011 | B14: CUST10011 | C14: 11/11/2024 | D14: Wire Transfer | E14: 38000 | F14: GBP | G14: James Okafor | H14: China | I14: Cross-border to FATF grey list | J14: Medium | K14: Yes | L14: File SAR | M14: A. Kumar | N14: 15/11/2024
A15: TXN40012 | B15: CUST10012 | C15: 12/12/2024 | D15: Cash Deposit | E15: 8500 | F15: AED | G15: Mei Lin | H15: India | I15: Off-hours bulk transfer | J15: Low | K15: Yes | L15: Freeze Transaction | M15: S. Patel | N15: 15/12/2024
A16: TXN40013 | B16: CUST10013 | C16: 13/01/2024 | D16: Cash Withdrawal | E16: 9800 | F16: USD | G16: Roberto Ferrari | H16: UK | I16: Inconsistent with profile | J16: High | K16: Yes | L16: Freeze Transaction | M16: M. Ali | N16: 21/01/2024
A17: TXN40014 | B17: CUST10014 | C17: 14/02/2024 | D17: SWIFT Transfer | E17: 38000 | F17: EUR | G17: Zara Khan | H17: Germany | I17: New beneficiary > $50K | J17: Medium | K17: Yes | L17: Block & Report | M17: R. Chen | N17: 21/02/2024
A18: TXN40015 | B18: CUST10015 | C18: 15/03/2024 | D18: Internal Transfer | E18: 110000 | F18: GBP | G18: David Nakamura | H18: Brazil | I18: Crypto off-ramp detected | J18: Low | K18: Yes | L18: Contact Customer | M18: J. Smith | N18: 23/03/2024
A19: TXN40016 | B19: CUST10016 | C19: 16/04/2024 | D19: Crypto Exchange | E19: 67000 | F19: AED | G19: Hassan Al-Amin | H19: UAE | I19: Amount > $10,000 Cash | J19: High | K19: Yes | L19: Request Documentation | M19: L. Wang | N19: 17/04/2024
A20: TXN40017 | B20: CUST10017 | C20: 17/05/2024 | D20: Real Estate Payment | E20: 48000 | F20: USD | G20: Sara Lindqvist | H20: Panama | I20: Rapid in-out same day | J20: Medium | K20: No | L20: Freeze Transaction | M20: P. Nair
A21: TXN40018 | B21: CUST10018 | C21: 18/06/2024 | D21: Trade Finance | E21: 100000 | F21: EUR | G21: Kwame Asante | H21: British Virgin Islands | I21: High-risk jurisdiction transfer | J21: Low | K21: Pending | L21: Block & Report | M21: F. Ahmed
A22: TXN40019 | B22: CUST10019 | C22: 19/07/2024 | D22: Card Transaction | E22: 11000 | F22: GBP | G22: Lena Svensson | H22: Cayman Islands | I22: Multiple transactions structuring | J22: High | K22: Pending | L22: Freeze Transaction | M22: T. Obi
A23: TXN40020 | B23: CUST10020 | C23: 20/08/2024 | D23: Loan Drawdown | E23: 48000 | F23: AED | G23: Felix Müller | H23: Switzerland | I23: Dormant account sudden activity | J23: Medium | K23: No | L23: Request Documentation | M23: Head AML
A24: TXN40021 | B24: CUST10021 | C24: 21/09/2024 | D24: Wire Transfer | E24: 42000 | F24: USD | G24: Amara Diallo | H24: Russia | I24: Round-dollar amounts | J24: Low | K24: Pending | L24: Refer to MLRO | M24: A. Kumar
A25: TXN40022 | B25: CUST10022 | C25: 22/10/2024 | D25: Cash Deposit | E25: 38000 | F25: EUR | G25: Ricardo Santos | H25: Nigeria | I25: Velocity threshold breach | J25: High | K25: Yes | L25: Block & Report | M25: S. Patel | N25: 01/11/2024
A26: TXN40023 | B26: CUST10023 | C26: 23/11/2024 | D26: Cash Withdrawal | E26: 6500 | F26: GBP | G26: Priya Kapoor | H26: Iran | I26: PEP counterparty | J26: Medium | K26: No | L26: Refer to MLRO | M26: M. Ali
A27: TXN40024 | B27: CUST10024 | C27: 24/12/2024 | D27: SWIFT Transfer | E27: 42000 | F27: AED | G27: Dmitri Volkov | H27: North Korea | I27: Sanctions list match | J27: Low | K27: Yes | L27: Block & Report | M27: R. Chen | N27: 01/01/2025
A28: TXN40025 | B28: CUST10025 | C28: 25/01/2024 | D28: Internal Transfer | E28: 55000 | F28: USD | G28: Aiko Tanaka | H28: Myanmar | I28: Unusual frequency pattern | J28: High | K28: Yes | L28: Monitor & Watch | M28: J. Smith | N28: 03/02/2024
A29: TXN40026 | B29: CUST10026 | C29: 26/02/2024 | D29: Crypto Exchange | E29: 175000 | F29: EUR | G29: Ibrahim Al-Farsi | H29: China | I29: Cross-border to FATF grey list | J29: Medium | K29: Yes | L29: Monitor & Watch | M29: L. Wang | N29: 05/03/2024
A30: TXN40027 | B30: CUST10027 | C30: 27/03/2024 | D30: Real Estate Payment | E30: 25000 | F30: GBP | G30: Grace Osei | H30: India | I30: Off-hours bulk transfer | J30: Low | K30: Yes | L30: Freeze Transaction | M30: P. Nair | N30: 01/04/2024
A31: TXN40028 | B31: CUST10028 | C31: 28/04/2024 | D31: Trade Finance | E31: 200000 | F31: AED | G31: Viktor Kozlov | H31: UK | I31: Inconsistent with profile | J31: High | K31: Yes | L31: Refer to MLRO | M31: F. Ahmed | N31: 30/04/2024
A32: TXN40029 | B32: CUST10029 | C32: 01/05/2024 | D32: Card Transaction | E32: 75000 | F32: USD | G32: Chen Holdings Ltd | H32: Germany | I32: New beneficiary > $50K | J32: Medium | K32: Yes | L32: Freeze Transaction | M32: T. Obi | N32: 08/05/2024
A33: TXN40030 | B33: CUST10030 | C33: 02/06/2024 | D33: Loan Drawdown | E33: 75000 | F33: EUR | G33: Layla Nasser | H33: Brazil | I33: Crypto off-ramp detected | J33: Low | K33: Yes | L33: File SAR | M33: Head AML | N33: 09/06/2024
A34: TXN40031 | B34: CUST10031 | C34: 03/07/2024 | D34: Wire Transfer | E34: 88000 | F34: GBP | G34: Isabella Costa | H34: UAE | I34: Amount > $10,000 Cash | J34: High | K34: Yes | L34: Refer to MLRO | M34: A. Kumar | N34: 11/07/2024
A35: TXN40032 | B35: CUST10032 | C35: 04/08/2024 | D35: Cash Deposit | E35: 88000 | F35: AED | G35: Mohammed Al-Sayed | H35: Panama | I35: Rapid in-out same day | J35: Medium | K35: Yes | L35: Freeze Transaction | M35: S. Patel | N35: 11/08/2024
A36: TXN40033 | B36: CUST10033 | C36: 05/09/2024 | D36: Cash Withdrawal | E36: 67000 | F36: USD | G36: Elena Marchetti | H36: British Virgin Islands | I36: High-risk jurisdiction transfer | J36: Low | K36: Pending | L36: Escalate to AML Team | M36: M. Ali
A37: TXN40034 | B37: CUST10034 | C37: 06/10/2024 | D37: SWIFT Transfer | E37: 110000 | F37: EUR | G37: James Fernandez | H37: Cayman Islands | I37: Multiple transactions structuring | J37: High | K37: No | L37: Block & Report | M37: R. Chen
A38: TXN40035 | B38: CUST10035 | C38: 07/11/2024 | D38: Internal Transfer | E38: 9800 | F38: GBP | G38: Yuki Tanaka | H38: Switzerland | I38: Dormant account sudden activity | J38: Medium | K38: Yes | L38: Monitor & Watch | M38: J. Smith | N38: 14/11/2024
A39: TXN40036 | B39: CUST10036 | C39: 08/12/2024 | D39: Crypto Exchange | E39: 88000 | F39: AED | G39: Ravi Krishnamurthy | H39: Russia | I39: Round-dollar amounts | J39: Low | K39: Pending | L39: Refer to MLRO | M39: L. Wang
A40: TXN40037 | B40: CUST10037 | C40: 09/01/2024 | D40: Real Estate Payment | E40: 38000 | F40: USD | G40: Astrid Bergström | H40: Nigeria | I40: Velocity threshold breach | J40: High | K40: Yes | L40: Block & Report | M40: P. Nair | N40: 13/01/2024
...

Sheet 📊 Power BI Guide
A1: POWER BI SETUP GUIDE | Fresher-Friendly Step-by-Step
A2: Connect this Excel file to Power BI and build a full AML/KYC compliance dashboard
A3: STEP 1 — CONNECT EXCEL TO POWER BI
A4: 1. Open Power BI Desktop → click 'Get Data' → choose 'Excel Workbook'
A5: 2. Browse and select: AML_KYC_EDD_Dashboard_50.xlsx
A6: 3. In Navigator, tick all sheets: KYC Register, AML Alerts, EDD Cases, SAR Log, Transaction Monitor, Risk Matrix
A7: 4. Click 'Transform Data' → Power Query opens → review data, then click 'Close & Apply'
A9: STEP 2 — BUILD KYC PAGE
A10: • Donut Chart: Legend = Risk Level, Values = Count of Cust ID
A11: • Stacked Column: X = KYC Status, Y = Count of Cust ID, Legend = Account Type
A12: • Table: Cust ID | Name | Risk Level | KYC Status | PEP Flag | Sanctions | Remarks
A13: • Cards: [Total Customers = 50] [PEP Count] [Sanctions Fails] [KYC % Verified]
... A56: ✅ Use Power Automate to send email alerts when High Risk alerts are created
